Workbook

Sheet 1. Portada y Resumen
A1: MUNICIPALIDAD METROPOLITANA DE LIMA · SISOL SALUD
A2: Documento de Asesoría · GSS · Mayo 2026
A4: PROYECTO GRAVE
A6: Grupo de Respuesta Avanzada para Vidas en Emergencia
A8: Costeo Financiero Completo del Piloto Metropolitano de Motos Paramédicas
A12: Dirigido a: | B12: Gerencia de Servicios de Salud — SISOL SALUD
A13: Elaborado por: | B13: Asesoría de Gerencia de Servicios de Salud
A14: Versión: | B14: Versión 2.0 — Mayo 2026
A15: Carácter: | B15: Trabajo interno · Confidencial
A17: RESUMEN EJECUTIVO DEL PILOTO
A19: Indicador clave | D19: Valor | F19: Observación
A20: Motos operativas | D20: 33 | F20: Distribuidas en 4 distritos
A21: Cobertura poblacional | D21: 2,073,965 habitantes | F21: 20% de Lima Metropolitana
A22: Personal operativo | D22: 201 personas | F22: 99 TEM + 99 enfermeros + 3 operadores
A23: Modalidad de contratación | D23: Tercerización por servicios | F23: Con SCTR obligatorio riesgo IV-V
A24: Tiempo de respuesta objetivo | D24: 5 a 8 minutos | F24: Frente a 20-30 min actual de ambulancia
A25: Operación | D25: 24/7 | F25: 2 turnos de 12 horas con factor cobertura 1.5
A26: Inversión inicial total | D26: S/ 1,640,800 | F26: Una sola vez al iniciar
A27: Gasto recurrente anual | D27: S/ 8,821,236 | F27: Operación 12 meses
A28: TOTAL año 1 | D28: S/ 10,462,036 | F28: Inversión + operación 12 meses
A29: Aporte MML | D29: 11.2% (S/ 1,174,800) | F29: Solo motos equipadas
A30: Aporte SISOL | D30: 88.8% (S/ 9,287,236) | F30: Resto del proyecto
A33: CONVENCIÓN DE COLORES (estándar financiero)
A34: Azul | B34: Datos modificables por el usuario (supuestos editables)
A35: Negro | B35: Fórmulas y cálculos automáticos
A36: Verde | B36: Referencias a otras hojas del libro
A37: Fondo amarillo claro | B37: Celdas de entrada modificables

Sheet 2. Supuestos
A1: SUPUESTOS DEL MODELO FINANCIERO
A2: Modifique las celdas con fondo amarillo para recalcular todos los cuadros automáticamente
A4: A. Parámetros generales del piloto
A5: Concepto | B5: Valor | C5: Unidad | D5: Fuente / Observación
A6: Número de motos del piloto | B6: 33 | C6: unidades | D6: PPT MML — distribución 4 distritos
A7: Distritos del piloto | B7: 4 | C7: distritos | D7: Ate, Comas, VMT, Cercado de Lima
A8: Población cubierta | B8: 2073965 | C8: habitantes | D8: INEI 2025
A9: Horas de operación diaria | B9: 24 | C9: horas | D9: Operación continua 24/7
A10: Días de operación al año | B10: 365 | C10: días | D10: Sin pausa
A11: Turnos por día | B11: 2 | C11: turnos | D11: 12 horas cada uno
A12: Factor de cobertura | B12: 1.5 | C12: ratio | D12: Descansos, vacaciones, licencias
A13: Número de personas por moto | B13: 2 | C13: personas | D13: 1 TEM + 1 Enfermero
A15: B. Honorarios y remuneraciones
A16: Concepto | B16: Valor | C16: Unidad | D16: Fuente / Observación
A17: Honorario mensual Conductor TEM | B17: 1800 | C17: S/ /mes | D17: Mercado local 2026
A18: Honorario mensual Enfermero BLS | B18: 3500 | C18: S/ /mes | D18: Mercado local 2026
A19: Honorario mensual Operador Central | B19: 2500 | C19: S/ /mes | D19: Mercado local 2026
A20: Margen del operador tercerizado | B20: 0.15 | C20: porcentaje | D20: 15% sobre honorarios base
A21: Tasa SCTR Salud | B21: 0.0155 | C21: porcentaje | D21: Obligatorio riesgo IV-V
A22: Tasa SCTR Pensiones | B22: 0.013 | C22: porcentaje | D22: Obligatorio
A23: Capacitación continua mensual por moto | B23: 250 | C23: S/ /mes | D23: BLS, PHTLS, manejo defensivo
A24: C. Inversión inicial MML por unidad
A25: Concepto | B25: Valor | C25: Unidad | D25: Fuente / Observación
A26: Moto Honda XRE 300 | B26: 24000 | C26: S/ | D26: Precio de referencia 2026
A27: Acondicionamiento y rotulado | B27: 1200 | C27: S/ | D27: Pintura, logos, identificación
A28: Topcase y maletas laterales | B28: 2800 | C28: S/ | D28: Topcase 55L + 2 maletas 35L
A29: Circulinas y sirena LED | B29: 2200 | C29: S/ | D29: Lightbar LED + sirena 100W
A30: GPS y rastreo satelital | B30: 1500 | C30: S/ | D30: GPS+GLONASS, 4G LTE
A31: Sistema de comunicaciones | B31: 1300 | C31: S/ | D31: Radio digital DMR/VHF
A32: Soporte tablet rugerizado | B32: 600 | C32: S/ | D32: Anti-vibración + cargador
A33: Defensas y protecciones | B33: 700 | C33: S/ | D33: Defensas tubulares y cubre cárter
A34: Mica frontal y asiento | B34: 500 | C34: S/ | D34: Para jornadas extendidas
A35: Instalación y certificación | B35: 800 | C35: S/ | D35: Eléctrico + certificación SUTRAN
A36: TOTAL inversión MML por unidad | B36: =SUM(B26:B35) -> 35600 | C36: S/ | D36: Suma fila por fila
A38: D. Inversión inicial SISOL por unidad (Maletín RRM)
A39: Concepto | B39: Valor | C39: Unidad | D39: Fuente / Observación
A40: Bolsillo A (rojo) — DEA + paro CR | B40: 6500 | C40: S/ | D40: Desfibrilador y mascarilla
A41: Bolsillo B (naranja) — Trauma | B41: 850 | C41: S/ | D41: Torniquetes CAT + hemostáticos
A42: Bolsillo C (azul) — Vía aérea | B42: 1800 | C42: S/ | D42: BVM + O2 portátil + cánulas
A43: Bolsillo D (morado) — Anafilaxia | B43: 950 | C43: S/ | D43: Adrenalina + medicamentos
...

Sheet 3. Costeo por Moto
A1: COSTEO POR UNA UNIDAD OPERATIVA — MODALIDAD TERCERIZACIÓN
A2: Cálculos basados en los supuestos editables de la hoja 2. Modifique esa hoja para recalcular automáticamente.
A4: A. COSTO FIJO MENSUAL DEL PERSONAL
A5: Concepto | B5: Cálculo | C5: Cantidad | D5: Honorario unitario | E5: Subtotal mensual | F5: Observación
A6: Conductor TEM | B6: 2 turnos × factor cobertura 1.5 | C6: =2*'2. Supuestos'!$B$12 -> 3 | D6: ='2. Supuestos'!$B$17 -> 1800 | E6: =C6*D6 -> 5400 | F6: Modalidad tercerización
A7: Enfermero asistencial BLS | B7: 2 turnos × factor cobertura 1.5 | C7: 5 | D7: ='2. Supuestos'!$B$18 -> 3500 | E7: =C7*D7 -> 17500 | F7: Modalidad tercerización
A8: Honorarios base por moto (suma) | B8: TEM + Enfermero | E8: =E6+E7 -> 22900 | F8: Total honorarios sin cargas
A9: Margen del tercero (15%) | B9: Sobre honorarios base | D9: ='2. Supuestos'!$B$20 -> 0.15 | E9: =E8*D9 -> 3435 | F9: Gestión administrativa
A10: SCTR Salud (1.55%) | B10: Obligatorio riesgo IV-V | D10: ='2. Supuestos'!$B$21 -> 0.0155 | E10: =E8*D10 -> 354.95 | F10: D.S. 003-98-SA
A11: SCTR Pensiones (1.30%) | B11: Obligatorio | D11: ='2. Supuestos'!$B$22 -> 0.013 | E11: =E8*D11 -> 297.7 | F11: D.S. 003-98-SA
A12: Capacitación continua mensualizada | B12: BLS, PHTLS, manejo defensivo | E12: ='2. Supuestos'!$B$23 -> 250 | F12: Por unidad
A13: TOTAL COSTO FIJO MENSUAL POR MOTO | E13: =E8+E9+E10+E11+E12 -> 27237.65
A15: B. COSTO VARIABLE MENSUAL POR MOTO
A16: Total costo variable mensual | E16: ='2. Supuestos'!$B$59 -> 2920 | F16: Detalle en hoja 2 sección E
A18: C. COSTO TOTAL POR MOTO
A19: Costo fijo mensual | E19: =E13 -> 27237.65 | F19: De sección A
A20: Costo variable mensual | E20: =E16 -> 2920 | F20: De sección B
A21: COSTO MENSUAL POR MOTO | E21: =E19+E20 -> 30157.65 | F21: Total fijo + variable
A22: COSTO ANUAL POR MOTO | E22: =E21*12 -> 361891.8 | F22: Mensual × 12 meses
A24: D. INVERSIÓN INICIAL POR MOTO (UNA SOLA VEZ)
A25: Aporte MML (motos y equipamiento técnico) | E25: ='2. Supuestos'!$B$36 -> 35600 | F25: Honda XRE 300 equipada
A26: Aporte SISOL (equipamiento médico) | E26: ='2. Supuestos'!$B$46 -> 12000 | F26: Maletín RRM completo
A27: INVERSIÓN INICIAL POR UNIDAD | E27: =E25+E26 -> 47600 | F27: MML + SISOL

Sheet 4. Central Despacho
A1: COSTEO DE LA CENTRAL DE DESPACHO
A2: Central operada en sede SISOL existente — 3 operadores tercerizados (1 por turno + factor cobertura)
A4: A. PERSONAL DE LA CENTRAL
A5: Concepto | B5: Detalle | C5: Cantidad | D5: Honorario unitario | E5: Subtotal mensual | F5: Observación
A6: Operadores de central tercerizados | B6: 2 turnos × factor cobertura 1.5 | C6: =2*'2. Supuestos'!$B$12 -> 3 | D6: ='2. Supuestos'!$B$19 -> 2500 | E6: =C6*D6 -> 7500 | F6: 1 operador por turno de 12 horas
A7: Honorarios base | E7: =E6 -> 7500
A8: Margen del tercero (15%) | B8: Sobre honorarios base | D8: ='2. Supuestos'!$B$20 -> 0.15 | E8: =E7*D8 -> 1125 | F8: Gestión administrativa
A9: SCTR Salud (1.55%) | B9: Obligatorio | D9: ='2. Supuestos'!$B$21 -> 0.0155 | E9: =E7*D9 -> 116.25 | F9: D.S. 003-98-SA
A10: SCTR Pensiones (1.30%) | B10: Obligatorio | D10: ='2. Supuestos'!$B$22 -> 0.013 | E10: =E7*D10 -> 97.5 | F10: D.S. 003-98-SA
A11: Subtotal personal central | E11: =E7+E8+E9+E10 -> 8838.75
A13: B. OTROS COSTOS OPERATIVOS DE LA CENTRAL
A14: Servicios (telefonía, internet) | E14: 1500 | F14: Prorrateado de SISOL existente
A15: Mantenimiento de software | E15: 1500 | F15: Plataforma de despacho
A16: Insumos administrativos | E16: 300 | F16: Papelería y otros
A17: Local, electricidad, agua | E17: 0 | F17: Cubierto por sede SISOL existente
A18: Subtotal otros costos | E18: =SUM(E14:E17) -> 3300
A20: C. RESUMEN DE LA CENTRAL
A21: Personal de central | E21: =E11 -> 8838.75 | F21: Sección A
A22: Otros costos operativos | E22: =E18 -> 3300 | F22: Sección B
A23: TOTAL CENTRAL MENSUAL | E23: =E21+E22 -> 12138.75 | F23: Personal + operación
A24: TOTAL CENTRAL ANUAL | E24: =E23*12 -> 145665 | F24: Mensual × 12
A25: INVERSIÓN INICIAL CENTRAL | E25: ='2. Supuestos'!$B$65 -> 70000 | F25: Software + capacitación

Sheet 5. Piloto 33 Motos
A1: PROYECCIÓN FINANCIERA DEL PILOTO COMPLETO
A2: Extrapolación del costeo unitario al piloto completo del proyecto
A4: A. INVERSIÓN INICIAL TOTAL DEL PILOTO
A5: Concepto | B5: Aporta | C5: Por unidad | D5: Cantidad | E5: Total (S/)
A6: Motos Honda XRE 300 equipadas | B6: MML | C6: ='2. Supuestos'!$B$36 -> 35600 | D6: ='2. Supuestos'!$B$6 -> 33 | E6: =C6*D6 -> 1174800
A7: Equipamiento médico (Maletín RRM) | B7: SISOL | C7: ='2. Supuestos'!$B$46 -> 12000 | D7: ='2. Supuestos'!$B$6 -> 33 | E7: =C7*D7 -> 396000
A8: Inversión inicial de la central | B8: SISOL | C8: ='4. Central Despacho'!$E$25 -> 70000 | D8: 1 | E8: =C8*D8 -> 70000
A9: TOTAL INVERSIÓN INICIAL | E9: =SUM(E6:E8) -> 1640800
A11: B. GASTO RECURRENTE MENSUAL DEL PILOTO
A12: Concepto | B12: Aporta | C12: Por unidad | D12: Cantidad | E12: Total (S/)
A13: Operación de motos (personal + insumos) | B13: SISOL | C13: ='3. Costeo por Moto'!$E$21 -> 30157.65 | D13: ='2. Supuestos'!$B$6 -> 33 | E13: =C13*D13 -> 995202.45
A14: Operación de la central | B14: SISOL | C14: ='4. Central Despacho'!$E$23 -> 12138.75 | D14: 1 | E14: =C14*D14 -> 12138.75
A15: TOTAL GASTO MENSUAL | E15: =SUM(E13:E14) -> 1007341.2
A16: TOTAL GASTO ANUAL (× 12 meses) | E16: =E15*12 -> 12088094
A18: C. PROYECCIÓN AÑO 1 COMPLETO
A19: Inversión inicial (una sola vez) | E19: =E9 -> 1640800
A20: Operación 12 meses | E20: =E16 -> 12088094
A21: TOTAL AÑO 1 DEL PROYECTO | E21: =E19+E20 -> 13728894
A23: D. DISTRIBUCIÓN DEL ESFUERZO FINANCIERO AÑO 1
A24: Institución | B24: Concepto | E24: Monto
A25: MUNICIPALIDAD METROPOLITANA DE LIMA | C25: Aporte único: motos equipadas | E25: =E6 -> 1174800
A26: SISOL SALUD | C26: Equipamiento + central + operación 12 meses | E26: =E7+E8+E20 -> 12554094
A27: TOTAL AÑO 1 | E27: =E25+E26 -> 13728894
A29: Porcentaje MML del total | E29: =E25/E27 -> 0.085571348
A30: Porcentaje SISOL del total | E30: =E26/E27 -> 0.91442865
A31: Ratio MML : SISOL | E31: =E26/E25 -> 10.686155
A33: 🚨 HALLAZGO CRÍTICO
A34: La distribución del esfuerzo financiero del año 1 muestra que SISOL asume la mayor carga económica del proyecto. Sin transferencia presupuestal explícita de la MML hacia SISOL para cubrir la operación recurrente, el proyecto NO ES FINANCIERAMENTE SOSTENIBLE para la red SISOL en el mediano plazo. SISOL debe condicionar su participación al aseguramiento del financiamiento por parte de la MML.

Sheet 6. Propuesta A vs B
A1: COMPARATIVO DE PROPUESTAS OPERATIVAS
A2: Propuesta A: Integración SAMU MINSA · Propuesta B: Central propia en sede SISOL
A4: Concepto | B4: PROPUESTA A — Integración SAMU | D4: PROPUESTA B — Central Propia
B5: Año 1 | C5: 5 años | D5: Año 1 | E5: 5 años
A6: Inversión inicial — Motos y equipamiento técnico (MML) | B6: ='5. Piloto 33 Motos'!E6 -> 1174800 | C6: =B6 -> 1174800 | D6: ='5. Piloto 33 Motos'!E6 -> 1174800 | E6: =D6 -> 1174800
A7: Inversión inicial — Equipamiento médico (SISOL) | B7: ='5. Piloto 33 Motos'!E7 -> 396000 | C7: =B7 -> 396000 | D7: ='5. Piloto 33 Motos'!E7 -> 396000 | E7: =D7 -> 396000
A8: Inversión inicial — Integración / Central | B8: 80000 | C8: =B8 -> 80000 | D8: ='5. Piloto 33 Motos'!E8 -> 70000 | E8: =D8 -> 70000
A9: TOTAL INVERSIÓN INICIAL | B9: =SUM(B6:B8) -> 1650800 | C9: =SUM(C6:C8) -> 1650800 | D9: =SUM(D6:D8) -> 1640800 | E9: =SUM(E6:E8) -> 1640800
A11: OPERACIÓN ANUAL
A12: Operación motos (33 unidades) | B12: ='5. Piloto 33 Motos'!E13*12 -> 11942429 | C12: =B12*5 -> 59712147 | D12: ='5. Piloto 33 Motos'!E13*12 -> 11942429 | E12: =D12*5 -> 59712147
A13: Operación central / integración SAMU | B13: 0 | C13: =B13*5 -> 0 | D13: ='4. Central Despacho'!$E$24 -> 145665 | E13: =D13*5 -> 728325
A14: TOTAL OPERACIÓN | B14: =SUM(B12:B13) -> 11942429 | C14: =SUM(C12:C13) -> 59712147 | D14: =SUM(D12:D13) -> 12088094 | E14: =SUM(E12:E13) -> 60440472
A16: GRAN TOTAL | B16: =B9+B14 -> 13593229 | C16: =C9+C14 -> 61362947 | D16: =D9+D14 -> 13728894 | E16: =E9+E14 -> 62081272
A18: Diferencia (B − A) | B18: =D16-B16 -> 135665 | D18: =E16-C16 -> 718325

Sheet 7. Proyección 5 Años
A1: PROYECCIÓN FINANCIERA A 5 AÑOS — PROPUESTA B (CENTRAL PROPIA)
A2: Asume incremento anual de 4% por inflación · Sin escalamiento de motos (mantiene 33)
A4: Tasa de inflación anual (editable): | D4: 0.04
A6: Concepto | B6: Año 1 2026 | C6: Año 2 2027 | D6: Año 3 2028 | E6: Año 4 2029 | F6: Año 5 2030 | G6: Acumulado
A7: Inversión inicial (única) | B7: ='5. Piloto 33 Motos'!E9 -> 1640800 | C7: 0 | D7: 0 | E7: 0 | F7: 0 | G7: =SUM(B7:F7) -> 1640800
A8: Operación motos (con inflación) | B8: ='5. Piloto 33 Motos'!E13*12 -> 11942429 | C8: =B8*(1+$D$4) -> 12420127 | D8: =C8*(1+$D$4) -> 12916932 | E8: =D8*(1+$D$4) -> 13433609 | F8: =E8*(1+$D$4) -> 13970953 | G8: =SUM(B8:F8) -> 64684050
A9: Operación central (con inflación) | B9: ='4. Central Despacho'!$E$24 -> 145665 | C9: =B9*(1+$D$4) -> 151491.6 | D9: =C9*(1+$D$4) -> 157551.26 | E9: =D9*(1+$D$4) -> 163853.31 | F9: =E9*(1+$D$4) -> 170407.45 | G9: =SUM(B9:F9) -> 788968.63
A10: TOTAL POR AÑO | B10: =SUM(B7:B9) -> 13728894 | C10: =SUM(C7:C9) -> 12571618 | D10: =SUM(D7:D9) -> 13074483 | E10: =SUM(E7:E9) -> 13597462 | F10: =SUM(F7:F9) -> 14141361 | G10: =SUM(B10:F10) -> 67113818
A11: TOTAL ACUMULADO | B11: =B10 -> 13728894 | C11: =B11+C10 -> 26300513 | D11: =C11+D10 -> 39374995 | E11: =D11+E10 -> 52972458 | F11: =E11+F10 -> 67113818 | G11: =F11 -> 67113818
